[2024-05-12T19:05:03.140+0000] {local_task_job_runner.py:120} INFO - ::group::Pre task execution logs
[2024-05-12T19:05:03.203+0000] {taskinstance.py:2076} INFO - Dependencies all met for dep_context=non-requeueable deps ti=<TaskInstance: Data_Extraction_Transformation_Loading_4.dvc_add manual__2024-05-12T18:28:05.864766+00:00 [queued]>
[2024-05-12T19:05:03.244+0000] {taskinstance.py:2076} INFO - Dependencies all met for dep_context=requeueable deps ti=<TaskInstance: Data_Extraction_Transformation_Loading_4.dvc_add manual__2024-05-12T18:28:05.864766+00:00 [queued]>
[2024-05-12T19:05:03.244+0000] {taskinstance.py:2306} INFO - Starting attempt 2 of 2
[2024-05-12T19:05:03.312+0000] {taskinstance.py:2330} INFO - Executing <Task(BashOperator): dvc_add> on 2024-05-12 18:28:05.864766+00:00
[2024-05-12T19:05:03.326+0000] {standard_task_runner.py:90} INFO - Running: ['airflow', 'tasks', 'run', 'Data_Extraction_Transformation_Loading_4', 'dvc_add', 'manual__2024-05-12T18:28:05.864766+00:00', '--job-id', '140', '--raw', '--subdir', 'DAGS_FOLDER/i202478_dag.py', '--cfg-path', '/tmp/tmpnbdymcsr']
[2024-05-12T19:05:03.329+0000] {standard_task_runner.py:91} INFO - Job 140: Subtask dvc_add
[2024-05-12T19:05:03.336+0000] {logging_mixin.py:188} WARNING - /home/airflow/.local/lib/python3.12/site-packages/airflow/task/task_runner/standard_task_runner.py:61 DeprecationWarning: This process (pid=781) is multi-threaded, use of fork() may lead to deadlocks in the child.
[2024-05-12T19:05:03.338+0000] {standard_task_runner.py:63} INFO - Started process 790 to run task
[2024-05-12T19:05:03.429+0000] {task_command.py:426} INFO - Running <TaskInstance: Data_Extraction_Transformation_Loading_4.dvc_add manual__2024-05-12T18:28:05.864766+00:00 [running]> on host da8cc0c3f69d
[2024-05-12T19:05:03.571+0000] {taskinstance.py:2648} INFO - Exporting env vars: AIRFLOW_CTX_DAG_OWNER='airflow' AIRFLOW_CTX_DAG_ID='Data_Extraction_Transformation_Loading_4' AIRFLOW_CTX_TASK_ID='dvc_add' AIRFLOW_CTX_EXECUTION_DATE='2024-05-12T18:28:05.864766+00:00' AIRFLOW_CTX_TRY_NUMBER='2' AIRFLOW_CTX_DAG_RUN_ID='manual__2024-05-12T18:28:05.864766+00:00'
[2024-05-12T19:05:03.573+0000] {taskinstance.py:430} INFO - ::endgroup::
[2024-05-12T19:05:03.592+0000] {subprocess.py:63} INFO - Tmp dir root location: /tmp
[2024-05-12T19:05:03.594+0000] {subprocess.py:75} INFO - Running command: ['/usr/bin/bash', '-c', 'dvc add /opt/airflow/dvc_repo/dataset_news_new.csv']
[2024-05-12T19:05:03.606+0000] {subprocess.py:86} INFO - Output:
[2024-05-12T19:05:04.717+0000] {subprocess.py:93} INFO - ERROR: you are not inside of a DVC repository (checked up to mount point '/')
[2024-05-12T19:05:04.872+0000] {subprocess.py:97} INFO - Command exited with return code 253
[2024-05-12T19:05:04.873+0000] {taskinstance.py:441} INFO - ::group::Post task execution logs
[2024-05-12T19:05:04.889+0000] {taskinstance.py:2905} ERROR - Task failed with exception
Traceback (most recent call last):
  File "/home/airflow/.local/lib/python3.12/site-packages/airflow/models/taskinstance.py", line 465, in _execute_task
    result = _execute_callable(context=context, **execute_callable_kwargs)
             ^^^^^^^^^^^^^^^^^^^^^^^^^^^^^^^^^^^^^^^^^^^^^^^^^^^^^^^^^^^^^
  File "/home/airflow/.local/lib/python3.12/site-packages/airflow/models/taskinstance.py", line 432, in _execute_callable
    return execute_callable(context=context, **execute_callable_kwargs)
           ^^^^^^^^^^^^^^^^^^^^^^^^^^^^^^^^^^^^^^^^^^^^^^^^^^^^^^^^^^^^
  File "/home/airflow/.local/lib/python3.12/site-packages/airflow/models/baseoperator.py", line 400, in wrapper
    return func(self, *args, **kwargs)
           ^^^^^^^^^^^^^^^^^^^^^^^^^^^
  File "/home/airflow/.local/lib/python3.12/site-packages/airflow/operators/bash.py", line 243, in execute
    raise AirflowException(
airflow.exceptions.AirflowException: Bash command failed. The command returned a non-zero exit code 253.
[2024-05-12T19:05:04.895+0000] {taskinstance.py:1206} INFO - Marking task as FAILED. dag_id=Data_Extraction_Transformation_Loading_4, task_id=dvc_add, run_id=manual__2024-05-12T18:28:05.864766+00:00, execution_date=20240512T182805, start_date=20240512T190503, end_date=20240512T190504
[2024-05-12T19:05:04.944+0000] {standard_task_runner.py:110} ERROR - Failed to execute job 140 for task dvc_add (Bash command failed. The command returned a non-zero exit code 253.; 790)
[2024-05-12T19:05:04.960+0000] {local_task_job_runner.py:240} INFO - Task exited with return code 1
[2024-05-12T19:05:04.992+0000] {taskinstance.py:3498} INFO - 0 downstream tasks scheduled from follow-on schedule check
[2024-05-12T19:05:05.017+0000] {local_task_job_runner.py:222} INFO - ::endgroup::
