[2024-05-12T18:59:55.996+0000] {local_task_job_runner.py:120} INFO - ::group::Pre task execution logs
[2024-05-12T18:59:56.044+0000] {taskinstance.py:2076} INFO - Dependencies all met for dep_context=non-requeueable deps ti=<TaskInstance: Data_Extraction_Transformation_Loading_4.dvc_add manual__2024-05-12T18:28:05.864766+00:00 [queued]>
[2024-05-12T18:59:56.061+0000] {taskinstance.py:2076} INFO - Dependencies all met for dep_context=requeueable deps ti=<TaskInstance: Data_Extraction_Transformation_Loading_4.dvc_add manual__2024-05-12T18:28:05.864766+00:00 [queued]>
[2024-05-12T18:59:56.061+0000] {taskinstance.py:2306} INFO - Starting attempt 1 of 2
[2024-05-12T18:59:56.101+0000] {taskinstance.py:2330} INFO - Executing <Task(BashOperator): dvc_add> on 2024-05-12 18:28:05.864766+00:00
[2024-05-12T18:59:56.110+0000] {standard_task_runner.py:90} INFO - Running: ['airflow', 'tasks', 'run', 'Data_Extraction_Transformation_Loading_4', 'dvc_add', 'manual__2024-05-12T18:28:05.864766+00:00', '--job-id', '138', '--raw', '--subdir', 'DAGS_FOLDER/i202478_dag.py', '--cfg-path', '/tmp/tmph6a1ku76']
[2024-05-12T18:59:56.112+0000] {standard_task_runner.py:91} INFO - Job 138: Subtask dvc_add
[2024-05-12T18:59:56.114+0000] {logging_mixin.py:188} WARNING - /home/airflow/.local/lib/python3.12/site-packages/airflow/task/task_runner/standard_task_runner.py:61 DeprecationWarning: This process (pid=735) is multi-threaded, use of fork() may lead to deadlocks in the child.
[2024-05-12T18:59:56.115+0000] {standard_task_runner.py:63} INFO - Started process 744 to run task
[2024-05-12T18:59:56.226+0000] {task_command.py:426} INFO - Running <TaskInstance: Data_Extraction_Transformation_Loading_4.dvc_add manual__2024-05-12T18:28:05.864766+00:00 [running]> on host da8cc0c3f69d
[2024-05-12T18:59:56.407+0000] {taskinstance.py:2648} INFO - Exporting env vars: AIRFLOW_CTX_DAG_OWNER='airflow' AIRFLOW_CTX_DAG_ID='Data_Extraction_Transformation_Loading_4' AIRFLOW_CTX_TASK_ID='dvc_add' AIRFLOW_CTX_EXECUTION_DATE='2024-05-12T18:28:05.864766+00:00' AIRFLOW_CTX_TRY_NUMBER='1' AIRFLOW_CTX_DAG_RUN_ID='manual__2024-05-12T18:28:05.864766+00:00'
[2024-05-12T18:59:56.410+0000] {taskinstance.py:430} INFO - ::endgroup::
[2024-05-12T18:59:56.440+0000] {subprocess.py:63} INFO - Tmp dir root location: /tmp
[2024-05-12T18:59:56.443+0000] {subprocess.py:75} INFO - Running command: ['/usr/bin/bash', '-c', 'dvc add /opt/airflow/dvc_repo/dataset_news_new.csv']
[2024-05-12T18:59:56.457+0000] {subprocess.py:86} INFO - Output:
[2024-05-12T18:59:57.737+0000] {subprocess.py:93} INFO - ERROR: you are not inside of a DVC repository (checked up to mount point '/')
[2024-05-12T18:59:57.923+0000] {subprocess.py:97} INFO - Command exited with return code 253
[2024-05-12T18:59:57.925+0000] {taskinstance.py:441} INFO - ::group::Post task execution logs
[2024-05-12T18:59:57.953+0000] {taskinstance.py:2905} ERROR - Task failed with exception
Traceback (most recent call last):
  File "/home/airflow/.local/lib/python3.12/site-packages/airflow/models/taskinstance.py", line 465, in _execute_task
    result = _execute_callable(context=context, **execute_callable_kwargs)
             ^^^^^^^^^^^^^^^^^^^^^^^^^^^^^^^^^^^^^^^^^^^^^^^^^^^^^^^^^^^^^
  File "/home/airflow/.local/lib/python3.12/site-packages/airflow/models/taskinstance.py", line 432, in _execute_callable
    return execute_callable(context=context, **execute_callable_kwargs)
           ^^^^^^^^^^^^^^^^^^^^^^^^^^^^^^^^^^^^^^^^^^^^^^^^^^^^^^^^^^^^
  File "/home/airflow/.local/lib/python3.12/site-packages/airflow/models/baseoperator.py", line 400, in wrapper
    return func(self, *args, **kwargs)
           ^^^^^^^^^^^^^^^^^^^^^^^^^^^
  File "/home/airflow/.local/lib/python3.12/site-packages/airflow/operators/bash.py", line 243, in execute
    raise AirflowException(
airflow.exceptions.AirflowException: Bash command failed. The command returned a non-zero exit code 253.
[2024-05-12T18:59:57.960+0000] {taskinstance.py:1206} INFO - Marking task as UP_FOR_RETRY. dag_id=Data_Extraction_Transformation_Loading_4, task_id=dvc_add, run_id=manual__2024-05-12T18:28:05.864766+00:00, execution_date=20240512T182805, start_date=20240512T185956, end_date=20240512T185957
[2024-05-12T18:59:58.001+0000] {standard_task_runner.py:110} ERROR - Failed to execute job 138 for task dvc_add (Bash command failed. The command returned a non-zero exit code 253.; 744)
[2024-05-12T18:59:58.019+0000] {local_task_job_runner.py:240} INFO - Task exited with return code 1
[2024-05-12T18:59:58.065+0000] {taskinstance.py:3498} INFO - 0 downstream tasks scheduled from follow-on schedule check
[2024-05-12T18:59:58.069+0000] {local_task_job_runner.py:222} INFO - ::endgroup::
