[2024-05-12T20:58:57.590+0000] {local_task_job_runner.py:120} INFO - ::group::Pre task execution logs
[2024-05-12T20:58:57.660+0000] {taskinstance.py:2076} INFO - Dependencies all met for dep_context=non-requeueable deps ti=<TaskInstance: Data_Extraction_Transformation_Loading.dvc_push manual__2024-05-12T20:40:30.453200+00:00 [queued]>
[2024-05-12T20:58:57.689+0000] {taskinstance.py:2076} INFO - Dependencies all met for dep_context=requeueable deps ti=<TaskInstance: Data_Extraction_Transformation_Loading.dvc_push manual__2024-05-12T20:40:30.453200+00:00 [queued]>
[2024-05-12T20:58:57.689+0000] {taskinstance.py:2306} INFO - Starting attempt 1 of 2
[2024-05-12T20:58:57.745+0000] {taskinstance.py:2330} INFO - Executing <Task(BashOperator): dvc_push> on 2024-05-12 20:40:30.453200+00:00
[2024-05-12T20:58:57.756+0000] {standard_task_runner.py:90} INFO - Running: ['airflow', 'tasks', 'run', 'Data_Extraction_Transformation_Loading', 'dvc_push', 'manual__2024-05-12T20:40:30.453200+00:00', '--job-id', '169', '--raw', '--subdir', 'DAGS_FOLDER/i202478_dag.py', '--cfg-path', '/tmp/tmpackqqmhw']
[2024-05-12T20:58:57.760+0000] {standard_task_runner.py:91} INFO - Job 169: Subtask dvc_push
[2024-05-12T20:58:57.765+0000] {logging_mixin.py:188} WARNING - /home/airflow/.local/lib/python3.12/site-packages/airflow/task/task_runner/standard_task_runner.py:61 DeprecationWarning: This process (pid=254) is multi-threaded, use of fork() may lead to deadlocks in the child.
[2024-05-12T20:58:57.766+0000] {standard_task_runner.py:63} INFO - Started process 279 to run task
[2024-05-12T20:58:57.899+0000] {task_command.py:426} INFO - Running <TaskInstance: Data_Extraction_Transformation_Loading.dvc_push manual__2024-05-12T20:40:30.453200+00:00 [running]> on host 3a6423a4af12
[2024-05-12T20:58:58.142+0000] {taskinstance.py:2648} INFO - Exporting env vars: AIRFLOW_CTX_DAG_OWNER='airflow' AIRFLOW_CTX_DAG_ID='Data_Extraction_Transformation_Loading' AIRFLOW_CTX_TASK_ID='dvc_push' AIRFLOW_CTX_EXECUTION_DATE='2024-05-12T20:40:30.453200+00:00' AIRFLOW_CTX_TRY_NUMBER='1' AIRFLOW_CTX_DAG_RUN_ID='manual__2024-05-12T20:40:30.453200+00:00'
[2024-05-12T20:58:58.144+0000] {taskinstance.py:430} INFO - ::endgroup::
[2024-05-12T20:58:58.167+0000] {subprocess.py:63} INFO - Tmp dir root location: /tmp
[2024-05-12T20:58:58.170+0000] {subprocess.py:75} INFO - Running command: ['/usr/bin/bash', '-c', 'cd /opt/airflow/dvc_repo && pwd && dvc push']
[2024-05-12T20:58:58.183+0000] {subprocess.py:86} INFO - Output:
[2024-05-12T20:58:58.188+0000] {subprocess.py:93} INFO - /opt/airflow/dvc_repo
[2024-05-12T20:59:00.225+0000] {subprocess.py:93} INFO - /home/airflow/.local/lib/python3.12/site-packages/oauth2client/_helpers.py:255: UserWarning: Cannot access /home/airflow/.cache/pydrive2fs/710796635688-iivsgbgsb6uv1fap6635dhvuei09o66c.apps.googleusercontent.com/default.json: No such file or directory
[2024-05-12T20:59:00.226+0000] {subprocess.py:93} INFO -   warnings.warn(_MISSING_FILE_MESSAGE.format(filename))
[2024-05-12T20:59:00.227+0000] {subprocess.py:93} INFO - Your browser has been opened to visit:
[2024-05-12T20:59:00.228+0000] {subprocess.py:93} INFO - 
[2024-05-12T20:59:00.229+0000] {subprocess.py:93} INFO -     https://accounts.google.com/o/oauth2/auth?client_id=710796635688-iivsgbgsb6uv1fap6635dhvuei09o66c.apps.googleusercontent.com&redirect_uri=http%3A%2F%2Flocalhost%3A8090%2F&scope=https%3A%2F%2Fwww.googleapis.com%2Fauth%2Fdrive+https%3A%2F%2Fwww.googleapis.com%2Fauth%2Fdrive.appdata&access_type=offline&response_type=code&approval_prompt=force
[2024-05-12T20:59:00.230+0000] {subprocess.py:93} INFO - 
