[2024-05-11T17:16:21.131+0000] {local_task_job_runner.py:120} INFO - ::group::Pre task execution logs
[2024-05-11T17:16:21.173+0000] {taskinstance.py:2076} INFO - Dependencies all met for dep_context=non-requeueable deps ti=<TaskInstance: Data_Extraction_Transformation_Loading.dvc_remote_add manual__2024-05-11T16:23:23.496870+00:00 [queued]>
[2024-05-11T17:16:21.190+0000] {taskinstance.py:2076} INFO - Dependencies all met for dep_context=requeueable deps ti=<TaskInstance: Data_Extraction_Transformation_Loading.dvc_remote_add manual__2024-05-11T16:23:23.496870+00:00 [queued]>
[2024-05-11T17:16:21.191+0000] {taskinstance.py:2306} INFO - Starting attempt 2 of 2
[2024-05-11T17:16:21.223+0000] {taskinstance.py:2330} INFO - Executing <Task(BashOperator): dvc_remote_add> on 2024-05-11 16:23:23.496870+00:00
[2024-05-11T17:16:21.230+0000] {standard_task_runner.py:90} INFO - Running: ['airflow', 'tasks', 'run', 'Data_Extraction_Transformation_Loading', 'dvc_remote_add', 'manual__2024-05-11T16:23:23.496870+00:00', '--job-id', '12', '--raw', '--subdir', 'DAGS_FOLDER/i202478_dag.py', '--cfg-path', '/tmp/tmpnnd_9t0b']
[2024-05-11T17:16:21.233+0000] {standard_task_runner.py:91} INFO - Job 12: Subtask dvc_remote_add
[2024-05-11T17:16:21.235+0000] {logging_mixin.py:188} WARNING - /home/airflow/.local/lib/python3.12/site-packages/airflow/task/task_runner/standard_task_runner.py:61 DeprecationWarning: This process (pid=157) is multi-threaded, use of fork() may lead to deadlocks in the child.
[2024-05-11T17:16:21.236+0000] {standard_task_runner.py:63} INFO - Started process 166 to run task
[2024-05-11T17:16:21.343+0000] {task_command.py:426} INFO - Running <TaskInstance: Data_Extraction_Transformation_Loading.dvc_remote_add manual__2024-05-11T16:23:23.496870+00:00 [running]> on host 3c55fa953450
[2024-05-11T17:16:21.451+0000] {taskinstance.py:2648} INFO - Exporting env vars: AIRFLOW_CTX_DAG_OWNER='airflow' AIRFLOW_CTX_DAG_ID='Data_Extraction_Transformation_Loading' AIRFLOW_CTX_TASK_ID='dvc_remote_add' AIRFLOW_CTX_EXECUTION_DATE='2024-05-11T16:23:23.496870+00:00' AIRFLOW_CTX_TRY_NUMBER='2' AIRFLOW_CTX_DAG_RUN_ID='manual__2024-05-11T16:23:23.496870+00:00'
[2024-05-11T17:16:21.453+0000] {taskinstance.py:430} INFO - ::endgroup::
[2024-05-11T17:16:21.467+0000] {subprocess.py:63} INFO - Tmp dir root location: /tmp
[2024-05-11T17:16:21.468+0000] {subprocess.py:75} INFO - Running command: ['/usr/bin/bash', '-c', 'dvc remote add -d my_google_drive gdrive://1i3kGKsxTKMw3-tN9wpJ6fHjrIOoFaO0j -f']
[2024-05-11T17:16:21.477+0000] {subprocess.py:86} INFO - Output:
[2024-05-11T17:16:21.479+0000] {subprocess.py:93} INFO - /usr/bin/bash: line 1: dvc: command not found
[2024-05-11T17:16:21.480+0000] {subprocess.py:97} INFO - Command exited with return code 127
[2024-05-11T17:16:21.481+0000] {taskinstance.py:441} INFO - ::group::Post task execution logs
[2024-05-11T17:16:21.495+0000] {taskinstance.py:2905} ERROR - Task failed with exception
Traceback (most recent call last):
  File "/home/airflow/.local/lib/python3.12/site-packages/airflow/models/taskinstance.py", line 465, in _execute_task
    result = _execute_callable(context=context, **execute_callable_kwargs)
             ^^^^^^^^^^^^^^^^^^^^^^^^^^^^^^^^^^^^^^^^^^^^^^^^^^^^^^^^^^^^^
  File "/home/airflow/.local/lib/python3.12/site-packages/airflow/models/taskinstance.py", line 432, in _execute_callable
    return execute_callable(context=context, **execute_callable_kwargs)
           ^^^^^^^^^^^^^^^^^^^^^^^^^^^^^^^^^^^^^^^^^^^^^^^^^^^^^^^^^^^^
  File "/home/airflow/.local/lib/python3.12/site-packages/airflow/models/baseoperator.py", line 400, in wrapper
    return func(self, *args, **kwargs)
           ^^^^^^^^^^^^^^^^^^^^^^^^^^^
  File "/home/airflow/.local/lib/python3.12/site-packages/airflow/operators/bash.py", line 243, in execute
    raise AirflowException(
airflow.exceptions.AirflowException: Bash command failed. The command returned a non-zero exit code 127.
[2024-05-11T17:16:21.502+0000] {taskinstance.py:1206} INFO - Marking task as FAILED. dag_id=Data_Extraction_Transformation_Loading, task_id=dvc_remote_add, run_id=manual__2024-05-11T16:23:23.496870+00:00, execution_date=20240511T162323, start_date=20240511T171621, end_date=20240511T171621
[2024-05-11T17:16:21.536+0000] {standard_task_runner.py:110} ERROR - Failed to execute job 12 for task dvc_remote_add (Bash command failed. The command returned a non-zero exit code 127.; 166)
[2024-05-11T17:16:21.571+0000] {local_task_job_runner.py:240} INFO - Task exited with return code 1
[2024-05-11T17:16:21.595+0000] {taskinstance.py:3498} INFO - 0 downstream tasks scheduled from follow-on schedule check
[2024-05-11T17:16:21.613+0000] {local_task_job_runner.py:222} INFO - ::endgroup::
