[2024-05-12T17:17:02.556+0000] {local_task_job_runner.py:120} INFO - ::group::Pre task execution logs
[2024-05-12T17:17:02.623+0000] {taskinstance.py:2076} INFO - Dependencies all met for dep_context=non-requeueable deps ti=<TaskInstance: Data_Extraction_Transformation_Loading_6.dvc_init manual__2024-05-12T17:16:24.669385+00:00 [queued]>
[2024-05-12T17:17:02.656+0000] {taskinstance.py:2076} INFO - Dependencies all met for dep_context=requeueable deps ti=<TaskInstance: Data_Extraction_Transformation_Loading_6.dvc_init manual__2024-05-12T17:16:24.669385+00:00 [queued]>
[2024-05-12T17:17:02.657+0000] {taskinstance.py:2306} INFO - Starting attempt 1 of 2
[2024-05-12T17:17:02.756+0000] {taskinstance.py:2330} INFO - Executing <Task(BashOperator): dvc_init> on 2024-05-12 17:16:24.669385+00:00
[2024-05-12T17:17:02.771+0000] {standard_task_runner.py:90} INFO - Running: ['airflow', 'tasks', 'run', 'Data_Extraction_Transformation_Loading_6', 'dvc_init', 'manual__2024-05-12T17:16:24.669385+00:00', '--job-id', '98', '--raw', '--subdir', 'DAGS_FOLDER/i202478_dag.py', '--cfg-path', '/tmp/tmpxigj2ml3']
[2024-05-12T17:17:02.773+0000] {standard_task_runner.py:91} INFO - Job 98: Subtask dvc_init
[2024-05-12T17:17:02.775+0000] {logging_mixin.py:188} WARNING - /home/airflow/.local/lib/python3.12/site-packages/airflow/task/task_runner/standard_task_runner.py:61 DeprecationWarning: This process (pid=223) is multi-threaded, use of fork() may lead to deadlocks in the child.
[2024-05-12T17:17:02.776+0000] {standard_task_runner.py:63} INFO - Started process 232 to run task
[2024-05-12T17:17:02.984+0000] {task_command.py:426} INFO - Running <TaskInstance: Data_Extraction_Transformation_Loading_6.dvc_init manual__2024-05-12T17:16:24.669385+00:00 [running]> on host 0c931294f372
[2024-05-12T17:17:03.274+0000] {taskinstance.py:2648} INFO - Exporting env vars: AIRFLOW_CTX_DAG_OWNER='airflow' AIRFLOW_CTX_DAG_ID='Data_Extraction_Transformation_Loading_6' AIRFLOW_CTX_TASK_ID='dvc_init' AIRFLOW_CTX_EXECUTION_DATE='2024-05-12T17:16:24.669385+00:00' AIRFLOW_CTX_TRY_NUMBER='1' AIRFLOW_CTX_DAG_RUN_ID='manual__2024-05-12T17:16:24.669385+00:00'
[2024-05-12T17:17:03.276+0000] {taskinstance.py:430} INFO - ::endgroup::
[2024-05-12T17:17:03.308+0000] {subprocess.py:63} INFO - Tmp dir root location: /tmp
[2024-05-12T17:17:03.314+0000] {subprocess.py:75} INFO - Running command: ['/usr/bin/bash', '-c', 'dvc init --force']
[2024-05-12T17:17:03.328+0000] {subprocess.py:86} INFO - Output:
[2024-05-12T17:17:04.805+0000] {subprocess.py:93} INFO - ERROR: failed to initiate DVC - /tmp/airflowtmpqmbf9epe is not tracked by any supported SCM tool (e.g. Git). Use `--no-scm` if you don't want to use any SCM or `--subdir` if initializing inside a subdirectory of a parent SCM repository.
[2024-05-12T17:17:05.004+0000] {subprocess.py:97} INFO - Command exited with return code 1
[2024-05-12T17:17:05.005+0000] {taskinstance.py:441} INFO - ::group::Post task execution logs
[2024-05-12T17:17:05.032+0000] {taskinstance.py:2905} ERROR - Task failed with exception
Traceback (most recent call last):
  File "/home/airflow/.local/lib/python3.12/site-packages/airflow/models/taskinstance.py", line 465, in _execute_task
    result = _execute_callable(context=context, **execute_callable_kwargs)
             ^^^^^^^^^^^^^^^^^^^^^^^^^^^^^^^^^^^^^^^^^^^^^^^^^^^^^^^^^^^^^
  File "/home/airflow/.local/lib/python3.12/site-packages/airflow/models/taskinstance.py", line 432, in _execute_callable
    return execute_callable(context=context, **execute_callable_kwargs)
           ^^^^^^^^^^^^^^^^^^^^^^^^^^^^^^^^^^^^^^^^^^^^^^^^^^^^^^^^^^^^
  File "/home/airflow/.local/lib/python3.12/site-packages/airflow/models/baseoperator.py", line 400, in wrapper
    return func(self, *args, **kwargs)
           ^^^^^^^^^^^^^^^^^^^^^^^^^^^
  File "/home/airflow/.local/lib/python3.12/site-packages/airflow/operators/bash.py", line 243, in execute
    raise AirflowException(
airflow.exceptions.AirflowException: Bash command failed. The command returned a non-zero exit code 1.
[2024-05-12T17:17:05.042+0000] {taskinstance.py:1206} INFO - Marking task as UP_FOR_RETRY. dag_id=Data_Extraction_Transformation_Loading_6, task_id=dvc_init, run_id=manual__2024-05-12T17:16:24.669385+00:00, execution_date=20240512T171624, start_date=20240512T171702, end_date=20240512T171705
[2024-05-12T17:17:05.112+0000] {standard_task_runner.py:110} ERROR - Failed to execute job 98 for task dvc_init (Bash command failed. The command returned a non-zero exit code 1.; 232)
[2024-05-12T17:17:05.130+0000] {local_task_job_runner.py:240} INFO - Task exited with return code 1
[2024-05-12T17:17:05.184+0000] {taskinstance.py:3498} INFO - 0 downstream tasks scheduled from follow-on schedule check
[2024-05-12T17:17:05.187+0000] {local_task_job_runner.py:222} INFO - ::endgroup::
