[2024-05-12T17:40:40.689+0000] {local_task_job_runner.py:120} INFO - ::group::Pre task execution logs
[2024-05-12T17:40:40.752+0000] {taskinstance.py:2076} INFO - Dependencies all met for dep_context=non-requeueable deps ti=<TaskInstance: Data_Extraction_Transformation_Loading.dvc_remote_add scheduled__2024-05-11T00:00:00+00:00 [queued]>
[2024-05-12T17:40:40.784+0000] {taskinstance.py:2076} INFO - Dependencies all met for dep_context=requeueable deps ti=<TaskInstance: Data_Extraction_Transformation_Loading.dvc_remote_add scheduled__2024-05-11T00:00:00+00:00 [queued]>
[2024-05-12T17:40:40.786+0000] {taskinstance.py:2306} INFO - Starting attempt 1 of 2
[2024-05-12T17:40:40.872+0000] {taskinstance.py:2330} INFO - Executing <Task(BashOperator): dvc_remote_add> on 2024-05-11 00:00:00+00:00
[2024-05-12T17:40:40.882+0000] {standard_task_runner.py:90} INFO - Running: ['airflow', 'tasks', 'run', 'Data_Extraction_Transformation_Loading', 'dvc_remote_add', 'scheduled__2024-05-11T00:00:00+00:00', '--job-id', '109', '--raw', '--subdir', 'DAGS_FOLDER/i202478_dag.py', '--cfg-path', '/tmp/tmpq11cn7qb']
[2024-05-12T17:40:40.886+0000] {standard_task_runner.py:91} INFO - Job 109: Subtask dvc_remote_add
[2024-05-12T17:40:40.893+0000] {logging_mixin.py:188} WARNING - /home/airflow/.local/lib/python3.12/site-packages/airflow/task/task_runner/standard_task_runner.py:61 DeprecationWarning: This process (pid=108) is multi-threaded, use of fork() may lead to deadlocks in the child.
[2024-05-12T17:40:40.895+0000] {standard_task_runner.py:63} INFO - Started process 117 to run task
[2024-05-12T17:40:41.078+0000] {task_command.py:426} INFO - Running <TaskInstance: Data_Extraction_Transformation_Loading.dvc_remote_add scheduled__2024-05-11T00:00:00+00:00 [running]> on host da8cc0c3f69d
[2024-05-12T17:40:41.435+0000] {taskinstance.py:2648} INFO - Exporting env vars: AIRFLOW_CTX_DAG_OWNER='airflow' AIRFLOW_CTX_DAG_ID='Data_Extraction_Transformation_Loading' AIRFLOW_CTX_TASK_ID='dvc_remote_add' AIRFLOW_CTX_EXECUTION_DATE='2024-05-11T00:00:00+00:00' AIRFLOW_CTX_TRY_NUMBER='1' AIRFLOW_CTX_DAG_RUN_ID='scheduled__2024-05-11T00:00:00+00:00'
[2024-05-12T17:40:41.437+0000] {taskinstance.py:430} INFO - ::endgroup::
[2024-05-12T17:40:41.470+0000] {subprocess.py:63} INFO - Tmp dir root location: /tmp
[2024-05-12T17:40:41.473+0000] {subprocess.py:75} INFO - Running command: ['/usr/bin/bash', '-c', 'dvc remote add -d my_google_drive gdrive://1i3kGKsxTKMw3-tN9wpJ6fHjrIOoFaO0j -f']
[2024-05-12T17:40:41.488+0000] {subprocess.py:86} INFO - Output:
[2024-05-12T17:40:44.726+0000] {subprocess.py:93} INFO - Setting 'my_google_drive' as a default remote.
[2024-05-12T17:40:44.727+0000] {subprocess.py:93} INFO - ERROR: configuration error - config file error: Not inside a DVC repo
[2024-05-12T17:40:45.195+0000] {subprocess.py:97} INFO - Command exited with return code 251
[2024-05-12T17:40:45.196+0000] {taskinstance.py:441} INFO - ::group::Post task execution logs
[2024-05-12T17:40:45.219+0000] {taskinstance.py:2905} ERROR - Task failed with exception
Traceback (most recent call last):
  File "/home/airflow/.local/lib/python3.12/site-packages/airflow/models/taskinstance.py", line 465, in _execute_task
    result = _execute_callable(context=context, **execute_callable_kwargs)
             ^^^^^^^^^^^^^^^^^^^^^^^^^^^^^^^^^^^^^^^^^^^^^^^^^^^^^^^^^^^^^
  File "/home/airflow/.local/lib/python3.12/site-packages/airflow/models/taskinstance.py", line 432, in _execute_callable
    return execute_callable(context=context, **execute_callable_kwargs)
           ^^^^^^^^^^^^^^^^^^^^^^^^^^^^^^^^^^^^^^^^^^^^^^^^^^^^^^^^^^^^
  File "/home/airflow/.local/lib/python3.12/site-packages/airflow/models/baseoperator.py", line 400, in wrapper
    return func(self, *args, **kwargs)
           ^^^^^^^^^^^^^^^^^^^^^^^^^^^
  File "/home/airflow/.local/lib/python3.12/site-packages/airflow/operators/bash.py", line 243, in execute
    raise AirflowException(
airflow.exceptions.AirflowException: Bash command failed. The command returned a non-zero exit code 251.
[2024-05-12T17:40:45.230+0000] {taskinstance.py:1206} INFO - Marking task as UP_FOR_RETRY. dag_id=Data_Extraction_Transformation_Loading, task_id=dvc_remote_add, run_id=scheduled__2024-05-11T00:00:00+00:00, execution_date=20240511T000000, start_date=20240512T174040, end_date=20240512T174045
[2024-05-12T17:40:45.313+0000] {standard_task_runner.py:110} ERROR - Failed to execute job 109 for task dvc_remote_add (Bash command failed. The command returned a non-zero exit code 251.; 117)
[2024-05-12T17:40:45.347+0000] {local_task_job_runner.py:240} INFO - Task exited with return code 1
[2024-05-12T17:40:45.399+0000] {taskinstance.py:3498} INFO - 0 downstream tasks scheduled from follow-on schedule check
[2024-05-12T17:40:45.402+0000] {local_task_job_runner.py:222} INFO - ::endgroup::
