[2024-05-11T17:40:34.040+0000] {task_context_logger.py:104} ERROR - Executor reports task instance <TaskInstance: Data_Extraction_Transformation_Loading_2.dvc_init manual__2024-05-11T17:39:08.552187+00:00 [queued]> finished (failed) although the task says it's queued. (Info: None) Was the task killed externally?
