[2024-05-12T17:59:02.875+0000] {local_task_job_runner.py:120} INFO - ::group::Pre task execution logs
[2024-05-12T17:59:02.943+0000] {taskinstance.py:2076} INFO - Dependencies all met for dep_context=non-requeueable deps ti=<TaskInstance: Data_Extraction_Transformation_Loading_3.dvc_remote_add manual__2024-05-12T17:58:00.875149+00:00 [queued]>
[2024-05-12T17:59:02.977+0000] {taskinstance.py:2076} INFO - Dependencies all met for dep_context=requeueable deps ti=<TaskInstance: Data_Extraction_Transformation_Loading_3.dvc_remote_add manual__2024-05-12T17:58:00.875149+00:00 [queued]>
[2024-05-12T17:59:02.978+0000] {taskinstance.py:2306} INFO - Starting attempt 1 of 2
[2024-05-12T17:59:03.052+0000] {taskinstance.py:2330} INFO - Executing <Task(BashOperator): dvc_remote_add> on 2024-05-12 17:58:00.875149+00:00
[2024-05-12T17:59:03.065+0000] {standard_task_runner.py:90} INFO - Running: ['airflow', 'tasks', 'run', 'Data_Extraction_Transformation_Loading_3', 'dvc_remote_add', 'manual__2024-05-12T17:58:00.875149+00:00', '--job-id', '124', '--raw', '--subdir', 'DAGS_FOLDER/i202478_dag.py', '--cfg-path', '/tmp/tmpu2c29ve2']
[2024-05-12T17:59:03.071+0000] {standard_task_runner.py:91} INFO - Job 124: Subtask dvc_remote_add
[2024-05-12T17:59:03.077+0000] {logging_mixin.py:188} WARNING - /home/airflow/.local/lib/python3.12/site-packages/airflow/task/task_runner/standard_task_runner.py:61 DeprecationWarning: This process (pid=380) is multi-threaded, use of fork() may lead to deadlocks in the child.
[2024-05-12T17:59:03.078+0000] {standard_task_runner.py:63} INFO - Started process 389 to run task
[2024-05-12T17:59:03.216+0000] {task_command.py:426} INFO - Running <TaskInstance: Data_Extraction_Transformation_Loading_3.dvc_remote_add manual__2024-05-12T17:58:00.875149+00:00 [running]> on host da8cc0c3f69d
[2024-05-12T17:59:03.484+0000] {taskinstance.py:2648} INFO - Exporting env vars: AIRFLOW_CTX_DAG_OWNER='airflow' AIRFLOW_CTX_DAG_ID='Data_Extraction_Transformation_Loading_3' AIRFLOW_CTX_TASK_ID='dvc_remote_add' AIRFLOW_CTX_EXECUTION_DATE='2024-05-12T17:58:00.875149+00:00' AIRFLOW_CTX_TRY_NUMBER='1' AIRFLOW_CTX_DAG_RUN_ID='manual__2024-05-12T17:58:00.875149+00:00'
[2024-05-12T17:59:03.488+0000] {taskinstance.py:430} INFO - ::endgroup::
[2024-05-12T17:59:03.504+0000] {subprocess.py:63} INFO - Tmp dir root location: /tmp
[2024-05-12T17:59:03.506+0000] {subprocess.py:75} INFO - Running command: ['/usr/bin/bash', '-c', 'dvc remote add -d my_google_drive gdrive://1i3kGKsxTKMw3-tN9wpJ6fHjrIOoFaO0j -f']
[2024-05-12T17:59:03.517+0000] {subprocess.py:86} INFO - Output:
[2024-05-12T17:59:05.186+0000] {subprocess.py:93} INFO - Setting 'my_google_drive' as a default remote.
[2024-05-12T17:59:05.188+0000] {subprocess.py:93} INFO - ERROR: configuration error - config file error: Not inside a DVC repo
[2024-05-12T17:59:05.488+0000] {subprocess.py:97} INFO - Command exited with return code 251
[2024-05-12T17:59:05.489+0000] {taskinstance.py:441} INFO - ::group::Post task execution logs
[2024-05-12T17:59:05.512+0000] {taskinstance.py:2905} ERROR - Task failed with exception
Traceback (most recent call last):
  File "/home/airflow/.local/lib/python3.12/site-packages/airflow/models/taskinstance.py", line 465, in _execute_task
    result = _execute_callable(context=context, **execute_callable_kwargs)
             ^^^^^^^^^^^^^^^^^^^^^^^^^^^^^^^^^^^^^^^^^^^^^^^^^^^^^^^^^^^^^
  File "/home/airflow/.local/lib/python3.12/site-packages/airflow/models/taskinstance.py", line 432, in _execute_callable
    return execute_callable(context=context, **execute_callable_kwargs)
           ^^^^^^^^^^^^^^^^^^^^^^^^^^^^^^^^^^^^^^^^^^^^^^^^^^^^^^^^^^^^
  File "/home/airflow/.local/lib/python3.12/site-packages/airflow/models/baseoperator.py", line 400, in wrapper
    return func(self, *args, **kwargs)
           ^^^^^^^^^^^^^^^^^^^^^^^^^^^
  File "/home/airflow/.local/lib/python3.12/site-packages/airflow/operators/bash.py", line 243, in execute
    raise AirflowException(
airflow.exceptions.AirflowException: Bash command failed. The command returned a non-zero exit code 251.
[2024-05-12T17:59:05.523+0000] {taskinstance.py:1206} INFO - Marking task as UP_FOR_RETRY. dag_id=Data_Extraction_Transformation_Loading_3, task_id=dvc_remote_add, run_id=manual__2024-05-12T17:58:00.875149+00:00, execution_date=20240512T175800, start_date=20240512T175902, end_date=20240512T175905
[2024-05-12T17:59:05.590+0000] {standard_task_runner.py:110} ERROR - Failed to execute job 124 for task dvc_remote_add (Bash command failed. The command returned a non-zero exit code 251.; 389)
[2024-05-12T17:59:05.629+0000] {local_task_job_runner.py:240} INFO - Task exited with return code 1
[2024-05-12T17:59:05.678+0000] {taskinstance.py:3498} INFO - 0 downstream tasks scheduled from follow-on schedule check
[2024-05-12T17:59:05.681+0000] {local_task_job_runner.py:222} INFO - ::endgroup::
