[2024-05-11T17:53:51.667+0000] {local_task_job_runner.py:120} INFO - ::group::Pre task execution logs
[2024-05-11T17:53:51.736+0000] {taskinstance.py:2076} INFO - Dependencies all met for dep_context=non-requeueable deps ti=<TaskInstance: Data_Extraction_Transformation_Loading_4.dvc_init manual__2024-05-11T17:52:25.696883+00:00 [queued]>
[2024-05-11T17:53:51.763+0000] {taskinstance.py:2076} INFO - Dependencies all met for dep_context=requeueable deps ti=<TaskInstance: Data_Extraction_Transformation_Loading_4.dvc_init manual__2024-05-11T17:52:25.696883+00:00 [queued]>
[2024-05-11T17:53:51.764+0000] {taskinstance.py:2306} INFO - Starting attempt 2 of 2
[2024-05-11T17:53:51.842+0000] {taskinstance.py:2330} INFO - Executing <Task(BashOperator): dvc_init> on 2024-05-11 17:52:25.696883+00:00
[2024-05-11T17:53:51.854+0000] {standard_task_runner.py:90} INFO - Running: ['airflow', 'tasks', 'run', 'Data_Extraction_Transformation_Loading_4', 'dvc_init', 'manual__2024-05-11T17:52:25.696883+00:00', '--job-id', '18', '--raw', '--subdir', 'DAGS_FOLDER/i202478_dag.py', '--cfg-path', '/tmp/tmpxpecuej_']
[2024-05-11T17:53:51.857+0000] {standard_task_runner.py:91} INFO - Job 18: Subtask dvc_init
[2024-05-11T17:53:51.871+0000] {logging_mixin.py:188} WARNING - /home/airflow/.local/lib/python3.12/site-packages/airflow/task/task_runner/standard_task_runner.py:61 DeprecationWarning: This process (pid=404) is multi-threaded, use of fork() may lead to deadlocks in the child.
[2024-05-11T17:53:51.872+0000] {standard_task_runner.py:63} INFO - Started process 413 to run task
[2024-05-11T17:53:52.031+0000] {task_command.py:426} INFO - Running <TaskInstance: Data_Extraction_Transformation_Loading_4.dvc_init manual__2024-05-11T17:52:25.696883+00:00 [running]> on host 3c55fa953450
[2024-05-11T17:53:52.246+0000] {taskinstance.py:2648} INFO - Exporting env vars: AIRFLOW_CTX_DAG_OWNER='airflow' AIRFLOW_CTX_DAG_ID='Data_Extraction_Transformation_Loading_4' AIRFLOW_CTX_TASK_ID='dvc_init' AIRFLOW_CTX_EXECUTION_DATE='2024-05-11T17:52:25.696883+00:00' AIRFLOW_CTX_TRY_NUMBER='2' AIRFLOW_CTX_DAG_RUN_ID='manual__2024-05-11T17:52:25.696883+00:00'
[2024-05-11T17:53:52.248+0000] {taskinstance.py:430} INFO - ::endgroup::
[2024-05-11T17:53:52.272+0000] {subprocess.py:63} INFO - Tmp dir root location: /tmp
[2024-05-11T17:53:52.274+0000] {subprocess.py:75} INFO - Running command: ['/usr/bin/bash', '-c', 'dvc init --force']
[2024-05-11T17:53:52.289+0000] {subprocess.py:86} INFO - Output:
[2024-05-11T17:53:52.292+0000] {subprocess.py:93} INFO - /usr/bin/bash: line 1: dvc: command not found
[2024-05-11T17:53:52.293+0000] {subprocess.py:97} INFO - Command exited with return code 127
[2024-05-11T17:53:52.294+0000] {taskinstance.py:441} INFO - ::group::Post task execution logs
[2024-05-11T17:53:52.327+0000] {taskinstance.py:2905} ERROR - Task failed with exception
Traceback (most recent call last):
  File "/home/airflow/.local/lib/python3.12/site-packages/airflow/models/taskinstance.py", line 465, in _execute_task
    result = _execute_callable(context=context, **execute_callable_kwargs)
             ^^^^^^^^^^^^^^^^^^^^^^^^^^^^^^^^^^^^^^^^^^^^^^^^^^^^^^^^^^^^^
  File "/home/airflow/.local/lib/python3.12/site-packages/airflow/models/taskinstance.py", line 432, in _execute_callable
    return execute_callable(context=context, **execute_callable_kwargs)
           ^^^^^^^^^^^^^^^^^^^^^^^^^^^^^^^^^^^^^^^^^^^^^^^^^^^^^^^^^^^^
  File "/home/airflow/.local/lib/python3.12/site-packages/airflow/models/baseoperator.py", line 400, in wrapper
    return func(self, *args, **kwargs)
           ^^^^^^^^^^^^^^^^^^^^^^^^^^^
  File "/home/airflow/.local/lib/python3.12/site-packages/airflow/operators/bash.py", line 243, in execute
    raise AirflowException(
airflow.exceptions.AirflowException: Bash command failed. The command returned a non-zero exit code 127.
[2024-05-11T17:53:52.338+0000] {taskinstance.py:1206} INFO - Marking task as FAILED. dag_id=Data_Extraction_Transformation_Loading_4, task_id=dvc_init, run_id=manual__2024-05-11T17:52:25.696883+00:00, execution_date=20240511T175225, start_date=20240511T175351, end_date=20240511T175352
[2024-05-11T17:53:52.421+0000] {standard_task_runner.py:110} ERROR - Failed to execute job 18 for task dvc_init (Bash command failed. The command returned a non-zero exit code 127.; 413)
[2024-05-11T17:53:52.453+0000] {local_task_job_runner.py:240} INFO - Task exited with return code 1
[2024-05-11T17:53:52.504+0000] {taskinstance.py:3498} INFO - 0 downstream tasks scheduled from follow-on schedule check
[2024-05-11T17:53:52.547+0000] {local_task_job_runner.py:222} INFO - ::endgroup::
