[2024-05-12T20:04:17.747+0000] {local_task_job_runner.py:120} INFO - ::group::Pre task execution logs
[2024-05-12T20:04:17.788+0000] {taskinstance.py:2076} INFO - Dependencies all met for dep_context=non-requeueable deps ti=<TaskInstance: Data_Extraction_Transformation_Loading_4.dvc_push manual__2024-05-12T19:48:33.399525+00:00 [queued]>
[2024-05-12T20:04:17.802+0000] {taskinstance.py:2076} INFO - Dependencies all met for dep_context=requeueable deps ti=<TaskInstance: Data_Extraction_Transformation_Loading_4.dvc_push manual__2024-05-12T19:48:33.399525+00:00 [queued]>
[2024-05-12T20:04:17.803+0000] {taskinstance.py:2306} INFO - Starting attempt 2 of 2
[2024-05-12T20:04:17.834+0000] {taskinstance.py:2330} INFO - Executing <Task(BashOperator): dvc_push> on 2024-05-12 19:48:33.399525+00:00
[2024-05-12T20:04:17.840+0000] {standard_task_runner.py:90} INFO - Running: ['airflow', 'tasks', 'run', 'Data_Extraction_Transformation_Loading_4', 'dvc_push', 'manual__2024-05-12T19:48:33.399525+00:00', '--job-id', '156', '--raw', '--subdir', 'DAGS_FOLDER/i202478_dag.py', '--cfg-path', '/tmp/tmpeyatg_m2']
[2024-05-12T20:04:17.843+0000] {standard_task_runner.py:91} INFO - Job 156: Subtask dvc_push
[2024-05-12T20:04:17.845+0000] {logging_mixin.py:188} WARNING - /home/airflow/.local/lib/python3.12/site-packages/airflow/task/task_runner/standard_task_runner.py:61 DeprecationWarning: This process (pid=1189) is multi-threaded, use of fork() may lead to deadlocks in the child.
[2024-05-12T20:04:17.845+0000] {standard_task_runner.py:63} INFO - Started process 1198 to run task
[2024-05-12T20:04:17.921+0000] {task_command.py:426} INFO - Running <TaskInstance: Data_Extraction_Transformation_Loading_4.dvc_push manual__2024-05-12T19:48:33.399525+00:00 [running]> on host da8cc0c3f69d
[2024-05-12T20:04:18.034+0000] {taskinstance.py:2648} INFO - Exporting env vars: AIRFLOW_CTX_DAG_OWNER='airflow' AIRFLOW_CTX_DAG_ID='Data_Extraction_Transformation_Loading_4' AIRFLOW_CTX_TASK_ID='dvc_push' AIRFLOW_CTX_EXECUTION_DATE='2024-05-12T19:48:33.399525+00:00' AIRFLOW_CTX_TRY_NUMBER='2' AIRFLOW_CTX_DAG_RUN_ID='manual__2024-05-12T19:48:33.399525+00:00'
[2024-05-12T20:04:18.035+0000] {taskinstance.py:430} INFO - ::endgroup::
[2024-05-12T20:04:18.047+0000] {subprocess.py:63} INFO - Tmp dir root location: /tmp
[2024-05-12T20:04:18.049+0000] {subprocess.py:75} INFO - Running command: ['/usr/bin/bash', '-c', 'cd /opt/airflow/dvc_repo && pwd && dvc push']
[2024-05-12T20:04:18.055+0000] {subprocess.py:86} INFO - Output:
[2024-05-12T20:04:18.060+0000] {subprocess.py:93} INFO - /opt/airflow/dvc_repo
[2024-05-12T20:04:19.049+0000] {subprocess.py:93} INFO - ERROR: unexpected error - gdrive is supported, but requires 'dvc-gdrive' to be installed: No module named 'dvc_gdrive'
[2024-05-12T20:04:19.050+0000] {subprocess.py:93} INFO - 
[2024-05-12T20:04:19.050+0000] {subprocess.py:93} INFO - Having any troubles? Hit us up at https://dvc.org/support, we are always happy to help!
[2024-05-12T20:04:19.193+0000] {subprocess.py:97} INFO - Command exited with return code 255
[2024-05-12T20:04:19.194+0000] {taskinstance.py:441} INFO - ::group::Post task execution logs
[2024-05-12T20:04:19.217+0000] {taskinstance.py:2905} ERROR - Task failed with exception
Traceback (most recent call last):
  File "/home/airflow/.local/lib/python3.12/site-packages/airflow/models/taskinstance.py", line 465, in _execute_task
    result = _execute_callable(context=context, **execute_callable_kwargs)
             ^^^^^^^^^^^^^^^^^^^^^^^^^^^^^^^^^^^^^^^^^^^^^^^^^^^^^^^^^^^^^
  File "/home/airflow/.local/lib/python3.12/site-packages/airflow/models/taskinstance.py", line 432, in _execute_callable
    return execute_callable(context=context, **execute_callable_kwargs)
           ^^^^^^^^^^^^^^^^^^^^^^^^^^^^^^^^^^^^^^^^^^^^^^^^^^^^^^^^^^^^
  File "/home/airflow/.local/lib/python3.12/site-packages/airflow/models/baseoperator.py", line 400, in wrapper
    return func(self, *args, **kwargs)
           ^^^^^^^^^^^^^^^^^^^^^^^^^^^
  File "/home/airflow/.local/lib/python3.12/site-packages/airflow/operators/bash.py", line 243, in execute
    raise AirflowException(
airflow.exceptions.AirflowException: Bash command failed. The command returned a non-zero exit code 255.
[2024-05-12T20:04:19.225+0000] {taskinstance.py:1206} INFO - Marking task as FAILED. dag_id=Data_Extraction_Transformation_Loading_4, task_id=dvc_push, run_id=manual__2024-05-12T19:48:33.399525+00:00, execution_date=20240512T194833, start_date=20240512T200417, end_date=20240512T200419
[2024-05-12T20:04:19.283+0000] {standard_task_runner.py:110} ERROR - Failed to execute job 156 for task dvc_push (Bash command failed. The command returned a non-zero exit code 255.; 1198)
[2024-05-12T20:04:19.306+0000] {local_task_job_runner.py:240} INFO - Task exited with return code 1
[2024-05-12T20:04:19.332+0000] {taskinstance.py:3498} INFO - 0 downstream tasks scheduled from follow-on schedule check
[2024-05-12T20:04:19.335+0000] {local_task_job_runner.py:222} INFO - ::endgroup::
