[2024-05-12T19:04:48.482+0000] {local_task_job_runner.py:120} INFO - ::group::Pre task execution logs
[2024-05-12T19:04:48.526+0000] {taskinstance.py:2076} INFO - Dependencies all met for dep_context=non-requeueable deps ti=<TaskInstance: Data_Extraction_Transformation_Loading_4.dvc_add scheduled__2024-05-11T00:00:00+00:00 [queued]>
[2024-05-12T19:04:48.548+0000] {taskinstance.py:2076} INFO - Dependencies all met for dep_context=requeueable deps ti=<TaskInstance: Data_Extraction_Transformation_Loading_4.dvc_add scheduled__2024-05-11T00:00:00+00:00 [queued]>
[2024-05-12T19:04:48.549+0000] {taskinstance.py:2306} INFO - Starting attempt 2 of 2
[2024-05-12T19:04:48.587+0000] {taskinstance.py:2330} INFO - Executing <Task(BashOperator): dvc_add> on 2024-05-11 00:00:00+00:00
[2024-05-12T19:04:48.599+0000] {standard_task_runner.py:90} INFO - Running: ['airflow', 'tasks', 'run', 'Data_Extraction_Transformation_Loading_4', 'dvc_add', 'scheduled__2024-05-11T00:00:00+00:00', '--job-id', '139', '--raw', '--subdir', 'DAGS_FOLDER/i202478_dag.py', '--cfg-path', '/tmp/tmpp35al77m']
[2024-05-12T19:04:48.601+0000] {standard_task_runner.py:91} INFO - Job 139: Subtask dvc_add
[2024-05-12T19:04:48.606+0000] {logging_mixin.py:188} WARNING - /home/airflow/.local/lib/python3.12/site-packages/airflow/task/task_runner/standard_task_runner.py:61 DeprecationWarning: This process (pid=767) is multi-threaded, use of fork() may lead to deadlocks in the child.
[2024-05-12T19:04:48.607+0000] {standard_task_runner.py:63} INFO - Started process 776 to run task
[2024-05-12T19:04:48.719+0000] {task_command.py:426} INFO - Running <TaskInstance: Data_Extraction_Transformation_Loading_4.dvc_add scheduled__2024-05-11T00:00:00+00:00 [running]> on host da8cc0c3f69d
[2024-05-12T19:04:48.846+0000] {taskinstance.py:2648} INFO - Exporting env vars: AIRFLOW_CTX_DAG_OWNER='airflow' AIRFLOW_CTX_DAG_ID='Data_Extraction_Transformation_Loading_4' AIRFLOW_CTX_TASK_ID='dvc_add' AIRFLOW_CTX_EXECUTION_DATE='2024-05-11T00:00:00+00:00' AIRFLOW_CTX_TRY_NUMBER='2' AIRFLOW_CTX_DAG_RUN_ID='scheduled__2024-05-11T00:00:00+00:00'
[2024-05-12T19:04:48.847+0000] {taskinstance.py:430} INFO - ::endgroup::
[2024-05-12T19:04:48.865+0000] {subprocess.py:63} INFO - Tmp dir root location: /tmp
[2024-05-12T19:04:48.866+0000] {subprocess.py:75} INFO - Running command: ['/usr/bin/bash', '-c', 'dvc add /opt/airflow/dvc_repo/dataset_news_new.csv']
[2024-05-12T19:04:48.877+0000] {subprocess.py:86} INFO - Output:
[2024-05-12T19:04:49.955+0000] {subprocess.py:93} INFO - ERROR: you are not inside of a DVC repository (checked up to mount point '/')
[2024-05-12T19:04:50.133+0000] {subprocess.py:97} INFO - Command exited with return code 253
[2024-05-12T19:04:50.134+0000] {taskinstance.py:441} INFO - ::group::Post task execution logs
[2024-05-12T19:04:50.152+0000] {taskinstance.py:2905} ERROR - Task failed with exception
Traceback (most recent call last):
  File "/home/airflow/.local/lib/python3.12/site-packages/airflow/models/taskinstance.py", line 465, in _execute_task
    result = _execute_callable(context=context, **execute_callable_kwargs)
             ^^^^^^^^^^^^^^^^^^^^^^^^^^^^^^^^^^^^^^^^^^^^^^^^^^^^^^^^^^^^^
  File "/home/airflow/.local/lib/python3.12/site-packages/airflow/models/taskinstance.py", line 432, in _execute_callable
    return execute_callable(context=context, **execute_callable_kwargs)
           ^^^^^^^^^^^^^^^^^^^^^^^^^^^^^^^^^^^^^^^^^^^^^^^^^^^^^^^^^^^^
  File "/home/airflow/.local/lib/python3.12/site-packages/airflow/models/baseoperator.py", line 400, in wrapper
    return func(self, *args, **kwargs)
           ^^^^^^^^^^^^^^^^^^^^^^^^^^^
  File "/home/airflow/.local/lib/python3.12/site-packages/airflow/operators/bash.py", line 243, in execute
    raise AirflowException(
airflow.exceptions.AirflowException: Bash command failed. The command returned a non-zero exit code 253.
[2024-05-12T19:04:50.158+0000] {taskinstance.py:1206} INFO - Marking task as FAILED. dag_id=Data_Extraction_Transformation_Loading_4, task_id=dvc_add, run_id=scheduled__2024-05-11T00:00:00+00:00, execution_date=20240511T000000, start_date=20240512T190448, end_date=20240512T190450
[2024-05-12T19:04:50.200+0000] {standard_task_runner.py:110} ERROR - Failed to execute job 139 for task dvc_add (Bash command failed. The command returned a non-zero exit code 253.; 776)
[2024-05-12T19:04:50.231+0000] {local_task_job_runner.py:240} INFO - Task exited with return code 1
[2024-05-12T19:04:50.272+0000] {taskinstance.py:3498} INFO - 0 downstream tasks scheduled from follow-on schedule check
[2024-05-12T19:04:50.299+0000] {local_task_job_runner.py:222} INFO - ::endgroup::
