[2024-05-12T18:00:01.913+0000] {local_task_job_runner.py:120} INFO - ::group::Pre task execution logs
[2024-05-12T18:00:01.994+0000] {taskinstance.py:2076} INFO - Dependencies all met for dep_context=non-requeueable deps ti=<TaskInstance: Data_Extraction_Transformation_Loading_3.dvc_remote_add scheduled__2024-05-11T00:00:00+00:00 [queued]>
[2024-05-12T18:00:02.026+0000] {taskinstance.py:2076} INFO - Dependencies all met for dep_context=requeueable deps ti=<TaskInstance: Data_Extraction_Transformation_Loading_3.dvc_remote_add scheduled__2024-05-11T00:00:00+00:00 [queued]>
[2024-05-12T18:00:02.027+0000] {taskinstance.py:2306} INFO - Starting attempt 2 of 2
[2024-05-12T18:00:02.107+0000] {taskinstance.py:2330} INFO - Executing <Task(BashOperator): dvc_remote_add> on 2024-05-11 00:00:00+00:00
[2024-05-12T18:00:02.129+0000] {logging_mixin.py:188} WARNING - /home/airflow/.local/lib/python3.12/site-packages/airflow/task/task_runner/standard_task_runner.py:61 DeprecationWarning: This process (pid=398) is multi-threaded, use of fork() may lead to deadlocks in the child.
[2024-05-12T18:00:02.123+0000] {standard_task_runner.py:90} INFO - Running: ['airflow', 'tasks', 'run', 'Data_Extraction_Transformation_Loading_3', 'dvc_remote_add', 'scheduled__2024-05-11T00:00:00+00:00', '--job-id', '125', '--raw', '--subdir', 'DAGS_FOLDER/i202478_dag.py', '--cfg-path', '/tmp/tmpx7zzfjva']
[2024-05-12T18:00:02.130+0000] {standard_task_runner.py:63} INFO - Started process 407 to run task
[2024-05-12T18:00:02.131+0000] {standard_task_runner.py:91} INFO - Job 125: Subtask dvc_remote_add
[2024-05-12T18:00:02.356+0000] {task_command.py:426} INFO - Running <TaskInstance: Data_Extraction_Transformation_Loading_3.dvc_remote_add scheduled__2024-05-11T00:00:00+00:00 [running]> on host da8cc0c3f69d
[2024-05-12T18:00:02.623+0000] {taskinstance.py:2648} INFO - Exporting env vars: AIRFLOW_CTX_DAG_OWNER='airflow' AIRFLOW_CTX_DAG_ID='Data_Extraction_Transformation_Loading_3' AIRFLOW_CTX_TASK_ID='dvc_remote_add' AIRFLOW_CTX_EXECUTION_DATE='2024-05-11T00:00:00+00:00' AIRFLOW_CTX_TRY_NUMBER='2' AIRFLOW_CTX_DAG_RUN_ID='scheduled__2024-05-11T00:00:00+00:00'
[2024-05-12T18:00:02.627+0000] {taskinstance.py:430} INFO - ::endgroup::
[2024-05-12T18:00:02.671+0000] {subprocess.py:63} INFO - Tmp dir root location: /tmp
[2024-05-12T18:00:02.673+0000] {subprocess.py:75} INFO - Running command: ['/usr/bin/bash', '-c', 'dvc remote add -d my_google_drive gdrive://1i3kGKsxTKMw3-tN9wpJ6fHjrIOoFaO0j -f']
[2024-05-12T18:00:02.690+0000] {subprocess.py:86} INFO - Output:
[2024-05-12T18:00:04.329+0000] {subprocess.py:93} INFO - Setting 'my_google_drive' as a default remote.
[2024-05-12T18:00:04.330+0000] {subprocess.py:93} INFO - ERROR: configuration error - config file error: Not inside a DVC repo
[2024-05-12T18:00:04.631+0000] {subprocess.py:97} INFO - Command exited with return code 251
[2024-05-12T18:00:04.634+0000] {taskinstance.py:441} INFO - ::group::Post task execution logs
[2024-05-12T18:00:04.669+0000] {taskinstance.py:2905} ERROR - Task failed with exception
Traceback (most recent call last):
  File "/home/airflow/.local/lib/python3.12/site-packages/airflow/models/taskinstance.py", line 465, in _execute_task
    result = _execute_callable(context=context, **execute_callable_kwargs)
             ^^^^^^^^^^^^^^^^^^^^^^^^^^^^^^^^^^^^^^^^^^^^^^^^^^^^^^^^^^^^^
  File "/home/airflow/.local/lib/python3.12/site-packages/airflow/models/taskinstance.py", line 432, in _execute_callable
    return execute_callable(context=context, **execute_callable_kwargs)
           ^^^^^^^^^^^^^^^^^^^^^^^^^^^^^^^^^^^^^^^^^^^^^^^^^^^^^^^^^^^^
  File "/home/airflow/.local/lib/python3.12/site-packages/airflow/models/baseoperator.py", line 400, in wrapper
    return func(self, *args, **kwargs)
           ^^^^^^^^^^^^^^^^^^^^^^^^^^^
  File "/home/airflow/.local/lib/python3.12/site-packages/airflow/operators/bash.py", line 243, in execute
    raise AirflowException(
airflow.exceptions.AirflowException: Bash command failed. The command returned a non-zero exit code 251.
[2024-05-12T18:00:04.676+0000] {taskinstance.py:1206} INFO - Marking task as FAILED. dag_id=Data_Extraction_Transformation_Loading_3, task_id=dvc_remote_add, run_id=scheduled__2024-05-11T00:00:00+00:00, execution_date=20240511T000000, start_date=20240512T180001, end_date=20240512T180004
[2024-05-12T18:00:04.741+0000] {standard_task_runner.py:110} ERROR - Failed to execute job 125 for task dvc_remote_add (Bash command failed. The command returned a non-zero exit code 251.; 407)
[2024-05-12T18:00:04.765+0000] {local_task_job_runner.py:240} INFO - Task exited with return code 1
[2024-05-12T18:00:04.827+0000] {taskinstance.py:3498} INFO - 0 downstream tasks scheduled from follow-on schedule check
[2024-05-12T18:00:04.871+0000] {local_task_job_runner.py:222} INFO - ::endgroup::
